no change     /shared/centos7/anaconda3/3.7/condabin/conda
no change     /shared/centos7/anaconda3/3.7/bin/conda
no change     /shared/centos7/anaconda3/3.7/bin/conda-env
no change     /shared/centos7/anaconda3/3.7/bin/activate
no change     /shared/centos7/anaconda3/3.7/bin/deactivate
no change     /shared/centos7/anaconda3/3.7/etc/profile.d/conda.sh
no change     /shared/centos7/anaconda3/3.7/etc/fish/conf.d/conda.fish
no change     /shared/centos7/anaconda3/3.7/shell/condabin/Conda.psm1
no change     /shared/centos7/anaconda3/3.7/shell/condabin/conda-hook.ps1
no change     /shared/centos7/anaconda3/3.7/lib/python3.7/site-packages/xontrib/conda.xsh
no change     /shared/centos7/anaconda3/3.7/etc/profile.d/conda.csh
no change     /home/eah.r/.bashrc
No action taken.
Traceback (most recent call last):
  File "/home/eah.r/.conda/envs/ee/lib/python3.7/site-packages/ee/data.py", line 338, in _execute_cloud_call
    return call.execute(num_retries=num_retries)
  File "/home/eah.r/.conda/envs/ee/lib/python3.7/site-packages/googleapiclient/_helpers.py", line 134, in positional_wrapper
    return wrapped(*args, **kwargs)
  File "/home/eah.r/.conda/envs/ee/lib/python3.7/site-packages/googleapiclient/http.py", line 915, in execute
    raise HttpError(resp, content, uri=self.uri)
googleapiclient.errors.HttpError: <HttpError 429 when requesting https://earthengine.googleapis.com/v1alpha/projects/earthengine-legacy/value:compute?prettyPrint=false&alt=json returned "Too Many Requests: Request was rejected because the request rate or concurrency limit was exceeded.". Details: "Too Many Requests: Request was rejected because the request rate or concurrency limit was exceeded.">

During handling of the above exception, another exception occurred:

Traceback (most recent call last):
  File "mine_detection.py", line 380, in <module>
    test_run = applyRoutine(region, 12, 1).getInfo()['features']
  File "/home/eah.r/.conda/envs/ee/lib/python3.7/site-packages/ee/collection.py", line 132, in getInfo
    return super(Collection, self).getInfo()
  File "/home/eah.r/.conda/envs/ee/lib/python3.7/site-packages/ee/computedobject.py", line 98, in getInfo
    return data.computeValue(self)
  File "/home/eah.r/.conda/envs/ee/lib/python3.7/site-packages/ee/data.py", line 742, in computeValue
    prettyPrint=False))['result']
  File "/home/eah.r/.conda/envs/ee/lib/python3.7/site-packages/ee/data.py", line 340, in _execute_cloud_call
    raise _translate_cloud_exception(e)
ee.ee_exception.EEException: Too Many Requests: Request was rejected because the request rate or concurrency limit was exceeded.
